<?xml version="1.0"?>
<robot name="kymco_maxxer90_front_wheel" xmlns:xacro="http://ros.org/wiki/xacro">

	<xacro:macro name="kymco_maxxer90_front_wheel" params="wheel_prefix *joint_pose">
		<link name="${wheel_prefix}_wheel_link">
            <inertial>
                <mass value="15.0"/>
                <origin xyz="0 0 0"/>
                <inertia  ixx="0.28813432952881635" ixy="0" ixz="0" iyy="0.5212991167201597" iyz="0" izz="0.2894147916616918" />
            </inertial>
			<visual>
				<origin xyz="0 0 0" rpy="0 0 0" />
				<geometry>
                    <mesh filename="package://kymco_maxxer90_description/meshes/wheel.stl" scale="1.0 1.0 1.0"/>
				</geometry>
				<material name="black"/>
			</visual>
			<collision>
                <origin xyz="0 0 0" rpy="0 0 0" />
				<geometry>
                    <mesh filename="package://kymco_maxxer90_description/meshes/wheel.stl" scale="1.0 1.0 1.0"/>
				</geometry>
			</collision>
		</link>

        <link name="${wheel_prefix}_wheel_steering_link" >
            <inertial>
                <mass value="1"/>
                <origin xyz="0 0 0"/>
                <inertia ixx="0.01" ixy="0" ixz="0" iyy="0.01" iyz="0" izz="0.01"/>
            </inertial>
        </link>

        <joint name="${wheel_prefix}_steering_wheel_joint" type="revolute">
			<xacro:insert_block name="joint_pose"/>
			<parent link="base_link"/>
			<child link="${wheel_prefix}_wheel_steering_link"/>
            <axis xyz="0 0 1" />
            <mimic joint="steering_wheel_joint" multiplier="1" offset="0" />
            <!-- TODO effort and velocity -->
            <limit lower="${-PI*25/180}" upper="${PI*25/180}" effort="100.5" velocity="4.5"/>
            <dynamics damping="3" friction="0.0" />
        </joint>

		<joint name="${wheel_prefix}_wheel" type="continuous">
            <origin xyz="0 0 0" rpy="0 0 0"/>
            <parent link="${wheel_prefix}_wheel_steering_link" />
			<child link="${wheel_prefix}_wheel_link"/>
			<axis xyz="0 1 0" rpy="0 0 0" />
        </joint>

        <gazebo reference="${wheel_prefix}_wheel_link">
            <material>Gazebo/Black</material>
        </gazebo>"

        <gazebo>
            <plugin name="${wheel_prefix}_mimic_joint_plugin" filename="libroboticsgroup_gazebo_mimic_joint_plugin.so">
                <joint>steering_wheel_joint</joint>
                <mimicJoint>${wheel_prefix}_steering_wheel_joint</mimicJoint>
                <hasPID/>
                <multiplier>1.0</multiplier>
                <offset>0</offset>
                <sensitiveness>0.1</sensitiveness>
                <maxEffort>100000.0</maxEffort>
            </plugin>
        </gazebo>

        <!-- <transmission name="${wheel_prefix}_wheel_steering_joint_trans"> -->
            <!-- <type>transmission_interface/SimpleTransmission</type> -->
            <!-- <joint name="${wheel_prefix}_steering_wheel_joint"> -->
                <!-- <hardwareInterface>hardware_interface/PositionJointInterface</hardwareInterface> -->
            <!-- </joint> -->
            <!-- <actuator name="${wheel_prefix}_steering_wheel_actuator"> -->
                <!-- <mechanicalReduction>1</mechanicalReduction> -->
            <!-- </actuator> -->
        <!-- </transmission> -->

        <!-- <transmission name="${wheel_prefix}_wheel_trans" type="SimpleTransmission"> -->
            <!-- <type>transmission_interface/SimpleTransmission</type> -->
            <!-- <actuator name="${wheel_prefix}_wheel_motor"> -->
                <!-- <mechanicalReduction>0</mechanicalReduction> -->
            <!-- </actuator> -->
            <!-- <joint name="${wheel_prefix}_wheel"> -->
                <!-- <hardwareInterface>hardware_interface/VelocityJointInterface</hardwareInterface> -->
            <!-- </joint> -->
        <!-- </transmission> -->

	</xacro:macro>
</robot>
