<?xml version="1.0"?>
<robot name="kymco_maxxer90_front_wheel" xmlns:xacro="http://ros.org/wiki/xacro">

	<xacro:macro name="kymco_maxxer90_front_wheel" params="wheel_prefix *joint_pose">
		<link name="${wheel_prefix}_wheel_link">
            <inertial>
                <mass value="8.0"/>
                <origin xyz="0 0 0"/>
                <inertia  ixx="0.11952" ixy="0" ixz="0" iyy="0.20903" iyz="0" izz="0.11952" />
            </inertial>
			<visual>
				<origin xyz="0 0 0" rpy="0 0 0" />
				<geometry>
                    <mesh filename="package://kymco_maxxer90_description/meshes/wheel.stl" scale="1.0 1.0 1.0"/>
				</geometry>
				<material name="black"/>
			</visual>
			<collision>
                <!-- <origin xyz="0 0 0" rpy="0 0 0" /> -->
                <origin xyz="0 0 0" rpy="${PI/2} 0 0" />
				<geometry>
                    <!-- <mesh filename="package://kymco_maxxer90_description/meshes/wheel.stl" scale="1.0 1.0 1.0"/> -->
                    <cylinder radius="0.2286" length="0.15" />
				</geometry>
			</collision>
		</link>

        <link name="${wheel_prefix}_wheel_steering_link" >
            <inertial>
                <mass value="1"/>
                <origin xyz="0 0 0"/>
                <inertia ixx="0.0001" ixy="0" ixz="0" iyy="0.0001" iyz="0" izz="0.0001"/>
            </inertial>
        </link>

        <link name="${wheel_prefix}_suspension_link" >
            <inertial>
                <mass value="1"/>
                <origin xyz="0 0 0"/>
                <inertia ixx="0.005" ixy="0" ixz="0" iyy="0.005" iyz="0" izz="0.005"/>
            </inertial>
        </link>

        <joint name="${wheel_prefix}_suspension_joint" type="prismatic">
			<xacro:insert_block name="joint_pose"/>
            <parent link="base_link"/>
            <child link="${wheel_prefix}_suspension_link"/>
            <axis xyz="0 0 -1" />
            <limit lower="-0.1" upper="0.1" effort="500" velocity="10"/>
        </joint>

        <gazebo reference="${wheel_prefix}_suspension_joint">
            <provideFeedback>true</provideFeedback>
            <implicitSpringDamper>true</implicitSpringDamper>
            <springStiffness>30000</springStiffness>
            <springReference>0</springReference>
        </gazebo>

        <transmission name="${wheel_prefix}_suspension_trans" type="SimpleTransmission">
            <type>transmission_interface/SimpleTransmission</type>
            <actuator name="${wheel_prefix}_suspension_actuator">
                <mechanicalReduction>1</mechanicalReduction>
            </actuator>
            <joint name="${wheel_prefix}_suspension_joint">
                <hardwareInterface>hardware_interface/EffortJointInterface</hardwareInterface>
            </joint>
        </transmission>
    
        <joint name="${wheel_prefix}_steering_wheel_joint" type="revolute">
            <origin xyz="0 0 0" rpy="0 0 0" /> 
            <parent link="${wheel_prefix}_suspension_link"/>
			<child link="${wheel_prefix}_wheel_steering_link"/>
            <axis xyz="0 0 1" />
            <mimic joint="steering_wheel_joint" multiplier="1" offset="0" />
            <limit lower="${-PI*25/180}" upper="${PI*25/180}" effort="100000" velocity="0.95"/>
            <dynamics damping="0" friction="1.0" />
        </joint>

		<joint name="${wheel_prefix}_wheel" type="continuous">
            <origin xyz="0 0 0" rpy="0 0 0"/>
            <parent link="${wheel_prefix}_wheel_steering_link" />
			<child link="${wheel_prefix}_wheel_link"/>
			<axis xyz="0 1 0" rpy="0 0 0" />
        </joint>

        <gazebo reference="${wheel_prefix}_wheel_link">
            <material>Gazebo/Black</material>
        </gazebo>"

        <transmission name="${wheel_prefix}_wheel_trans" type="SimpleTransmission">
            <type>transmission_interface/SimpleTransmission</type>
            <actuator name="${wheel_prefix}_wheel_actuator">
                <mechanicalReduction>0</mechanicalReduction>
            </actuator>
            <joint name="${wheel_prefix}_wheel">
                <hardwareInterface>hardware_interface/EffortJointInterface</hardwareInterface>
            </joint>
        </transmission>
    
        <gazebo>
            <plugin name="${wheel_prefix}_mimic_joint_plugin" filename="libroboticsgroup_gazebo_mimic_joint_plugin.so">
                <joint>steering_wheel_joint</joint>
                <mimicJoint>${wheel_prefix}_steering_wheel_joint</mimicJoint>
                <hasPID/>
                <multiplier>1.0</multiplier>
                <offset>0</offset>
                <sensitiveness>0.0</sensitiveness>
                <maxEffort>1000000.0</maxEffort>
            </plugin>
        </gazebo>

	</xacro:macro>
</robot>
