<?xml version="1.0"?>
<robot name="kymco_maxxer90_wheel" xmlns:xacro="http://ros.org/wiki/xacro">

	<xacro:macro name="kymco_maxxer90_wheel" params="wheel_prefix *joint_pose">
		<link name="${wheel_prefix}_wheel_link">
			<inertial>
				<mass value="10.0" />
                <origin xyz="0 0 0" />
                <inertia  ixx="0.1494" ixy="0" ixz="0" iyy="0.2613" iyz="0" izz="0.1494" />
			</inertial>
			<visual>
                <origin xyz="0 0 0" rpy="0 0 0" />
				<geometry>
                    <mesh filename="package://kymco_maxxer90_description/meshes/wheel.stl" scale="1.0 1.0 1.0"/>
				</geometry>
				<material name="black"/>
			</visual>
			<collision>
                <!-- <origin xyz="0 0 0" rpy="0 0 0" /> -->
                <origin xyz="0 0 0" rpy="${PI/2} 0 0" />
				<geometry>
                    <!-- <mesh filename="package://kymco_maxxer90_description/meshes/wheel.stl" scale="1.0 1.0 1.0"/> -->
                    <cylinder radius="0.2286" length="0.15" />
				</geometry>
			</collision>
		</link>

		<joint name="${wheel_prefix}_wheel" type="continuous">
			<parent link="RWD"/>
			<child link="${wheel_prefix}_wheel_link"/>
			<xacro:insert_block name="joint_pose"/>
			<axis xyz="0 1 0" rpy="0 0 0" />
            <dynamics damping="1" friction="1" />
		</joint>

        <gazebo reference="${wheel_prefix}_wheel_link">
            <material>Gazebo/Black</material>
        </gazebo>"

        <transmission name="${wheel_prefix}_wheel_trans" type="SimpleTransmission">
            <type>transmission_interface/SimpleTransmission</type>
            <actuator name="${wheel_prefix}_wheel_motor">
                <mechanicalReduction>1</mechanicalReduction>
            </actuator>
            <joint name="${wheel_prefix}_wheel">
                <hardwareInterface>hardware_interface/VelocityJointInterface</hardwareInterface>
            </joint>
        </transmission>

	</xacro:macro>
</robot>
